Workbook

Sheet baseDr_vs_DrCCTProf
B1: For_SPEC_TEST is not defined | E1: For_SPEC_TEST is defined
B2: BaseDr (ms) | C2: DrCCTProf (ms) | D2: Slowdown (DrCCTProf/Base) | E2: BaseDr (ms) | F2: DrCCTProf (ms) | G2: Slowdown (DrCCTProf/Base)
A3: perlbench_s | B3: 101944 | C3: 818999 | D3: =C3/B3 -> 8.0338127 | E3: 98501 | F3: 809954 | G3: =F3/E3 -> 8.2227998
A4: gcc_s | B4: 1142584 | C4: 35170 | D4: =C4/B4 -> 0.030781107 | E4: 1173327 | F4: 4494975 | G4: =F4/E4 -> 3.8309653
A5: mcf_s | B5: 1802901 | C5: 18869877 | D5: =C5/B5 -> 10.466397 | E5: 1912258 | F5: 19082397 | G5: =F5/E5 -> 9.9789866
A6: cactuBSSN_s | B6: 6461054 | C6: 13062885 | D6: =C6/B6 -> 2.0217886 | E6: 6670799 | F6: 13070879 | G6: =F6/E6 -> 1.9594173
A7: lbm_s | B7: 2993125 | C7: 3129927 | D7: =C7/B7 -> 1.0457054 | E7: 2873689 | F7: 2847569 | G7: =F7/E7 -> 0.99091064
A8: omnetpp_s | B8: 1280684 | C8: 12190915 | D8: =C8/B8 -> 9.5190656 | E8: 1334268 | F8: 12345570 | G8: =F8/E8 -> 9.2526914
A9: xalancbmk_s | B9: 848168 | C9: 6151126 | D9: =C9/B9 -> 7.2522496 | E9: 808898 | F9: 6075869 | G9: =F9/E9 -> 7.5112919
A10: x264_s | B10: 425669 | C10: 1545388 | D10: =C10/B10 -> 3.6304922 | E10: 417002 | F10: 1585570 | G10: =F10/E10 -> 3.8023079
A11: deepsjeng | B11: 1502111 | C11: 47107 | D11: =C11/B11 -> 0.031360532 | E11: 1475028 | F11: 6732182 | G11: =F11/E11 -> 4.5641045
A12: imagick_s | B12: 31466568 | C12: 40245088 | D12: =C12/B12 -> 1.2789793 | E12: 31952506 | F12: 40323858 | G12: =F12/E12 -> 1.2619936
A13: leela_s | B13: 1807025 | C13: 42216447 | D13: =C13/B13 -> 23.362403 | E13: 1839930 | F13: 41846821 | G13: =F13/E13 -> 22.743703
A14: nab_s | B14: 6162145 | C14: 27247050 | D14: =C14/B14 -> 4.4216827 | E14: 6122347 | F14: 26869851 | G14: =F14/E14 -> 4.3888154
A15: xz_s | B15: 20593 | C15: 33219 | D15: =C15/B15 -> 1.613121 | E15: 20555 | F15: 28571 | G15: =F15/E15 -> 1.3899781
A16: [drcctlib[fwk](hpcserver.cse.tamu.edu5493) msg]====Preallocated IPNodes exhausted. CCTLib couldn't fit your application in its memory. Try a smaller program.
B18: For_SPEC_TEST is not defiened | C18: For_SPEC_TEST is defiened
A19: For_SPEC_TEST is not defined | B19: Max Context Handle | C19: Max Context Handle
A20: perlbench_s | B20: 473465 | C20: 473190
A21: gcc_s | B21: 16777216 | C21: 149044545
A22: mcf_s | B22: 7789 | C22: 7789
A23: cactuBSSN_s | B23: 603451 | C23: 603448
A24: lbm_s | B24: 942 | C24: 942
A25: omnetpp_s | B25: 236131 | C25: 236113
A26: xalancbmk_s | B26: 155950 | C26: 155950
A27: x264_s | B27: 44151 | C27: 44149
A28: deepsjeng | B28: 16777216 | C28: 2147483647
A29: imagick_s | B29: 49506 | C29: 49505
A30: leela_s | B30: 7860845 | C30: 7860845
A31: nab_s | B31: 7987 | C31: 7987
A32: xz_s | B32: 954 | C32: 954

Sheet MaxCCID
B1: DrCCTLibProf | C1: DCCE (MaxID) | D1: PCCE (Recursive) - Sum of numCCs | E1: no. Back edges | J1: wpa: /home/sungkeun/git/DCCE/SVF/llvm-12.0.0.obj/include/llvm/IR/Function.h:781: llvm::Argument* llvm::Function::getArg(unsigned int) const: Assertion `i < NumArgs && "getArg() out of range!"' failed.
A2: 508.namd_r | C2: 16227 | D2: 16228 | E2: 0
A3: 510.parest_r
A4: 511.povray_r
A5: 600.perlbench_s | B5: 473190 | C5: 3.0698198e+81 | D5: 1.0819829e+65 | E5: 11699
A6: 602.gcc_s | B6: 149044545
A7: 605.mcf_s | B7: 7789 | C7: 274 | D7: 304 | E7: 1
A8: 607.cactuBSSN_s | B8: 603448
A9: 619.lbm_s | B9: 942 | C9: 95 | D9: 96 | E9: 0
A10: 620.omnetpp_s | B10: 236113
A11: 623.xalancbmk_s | B11: 155950 | C11: 1.2589179e+16 | D11: 19894985784 | E11: 327
A12: 625.x264_s | B12: 44149 | C12: 21350563 | D12: 21368452 | E12: 1
A13: 631.deepsjeng_s | B13: 2147483647 | C13: 31931071 | D13: 219943 | E13: 12
A14: 638.imagick_s | B14: 49505 | C14: 1.6332216e+47 | D14: 2.5614589e+20 | E14: 854
A15: 641.leela_s | B15: 7860845 | C15: 22464 | D15: 17574 | E15: 18
A16: 644.nab_s | B16: 7987 | C16: 103553 | D16: 34703 | E16: 24
A17: 657.xz_s | B17: 954 | C17: 3666 | D17: 3618 | E17: 13

Sheet Call Graph Statistics
E1: SVF | M1: DCCE | N1: PCCE | O1: Valence
E2: Nodes | L2: Cyclic Edges | M2: MaxID | N2: Sum(numCC) | O2: Nodes | P2: Edges | Q2: Cyclick Edges
C3: Language | D3: KLOC | E3: Reachable nodes | F3: Not Reachable | G3: Total | H3: Indirect Calls | I3: Reachable Edge | J3: Total | K3: max_num_callees
B4: 508.namd_r | C4: C++ | D4: 8 | E4: =G4-F4 -> 118 | F4: 29 | G4: 147 | H4: 83 | I4: 1976 | J4: 2501 | K4: 6 | L4: 0 | M4: 16227 | N4: 16228 | O4: 61 | P4: 553 | Q4: 0
B5: 510.parest_r | C5: C++ | D5: 427 | O5: 1315 | P5: 15080 | Q5: 200
B6: 511.povray_r | C6: C++,C | D6: 170 | O6: 519 | P6: 825 | Q6: 2380
B7: 600.perlbench_s | C7: C | D7: 362 | E7: =G7-F7 -> 2019 | F7: 342 | G7: 2361 | H7: 44557 | I7: 68965 | J7: 70468 | K7: 326 | L7: 11699 | M7: 3.0698198e+81 | N7: 1.0819829e+65
B8: 602.gcc_s | C8: C | D8: 1304 | O8: 19011 | P8: 131388 | Q8: 28330
B9: 605.mcf_s | C9: C | D9: 3 | E9: =G9-F9 -> 46 | F9: 4 | G9: 50 | H9: 60 | I9: 179 | J9: 189 | K9: 2 | L9: 1 | M9: 274 | N9: 304 | O9: 32 | P9: 126 | Q9: 1
B10: 607.cactuBSSN_s | C10: C++,C,Fortran | D10: 257 | O10: 1048 | P10: 22820 | Q10: 67
B11: 619.lbm_s | C11: C | D11: 1 | E11: =G11-F11 -> 31 | F11: 12 | G11: 43 | H11: 0 | I11: 73 | J11: 94 | K11: 0 | L11: 0 | M11: 95 | N11: 96 | O11: 17 | P11: 27 | Q11: 0
B12: 620.omnetpp_s | C12: C++ | D12: 134
B13: 623.xalancbmk_s | C13: C++ | D13: 520 | E13: =G13-F13 -> 1125 | F13: 9351 | G13: 10476 | H13: 6914 | I13: 6245 | J13: 54332 | K13: 57 | L13: 327 | M13: 1.2589179e+16 | N13: 19894985784 | O13: 4055 | P13: 22848 | Q13: 1566
B14: 625.x264_s | C14: C | D14: 96 | E14: =G14-F14 -> 519 | F14: 5 | G14: 524 | H14: 17731 | I14: 21213 | J14: 21228 | K14: 36 | L14: 1 | M14: 21350563 | N14: 21368452 | O14: 367 | P14: 2318 | Q14: 2
B15: 631.deepsjeng_s | C15: C++ | D15: 10 | E15: =G15-F15 -> 100 | F15: 24 | G15: 124 | H15: 0 | I15: 642 | J15: 759 | K15: 0 | L15: 12 | M15: 31931071 | N15: 219943 | O15: 87 | P15: 573 | Q15: 12
B16: 638.imagick_s | C16: C | D16: 259 | E16: =G16-F16 -> 1069 | F16: 1219 | G16: 2288 | H16: 545 | I16: 21560 | J16: 34003 | K16: 19 | L16: 854 | M16: 1.6332216e+47 | N16: 2.5614589e+20 | O16: 915 | P16: 18864 | Q16: 524
B17: 641.leela_s | C17: C++ | D17: 21 | E17: =G17-F17 -> 242 | F17: 104 | G17: 346 | H17: 78 | I17: 1122 | J17: 2072 | K17: 1 | L17: 18 | M17: 22464 | N17: 17574 | O17: 204 | P17: 1013 | Q17: 23
B18: 644.nab_s | C18: C | D18: 24 | E18: =G18-F18 -> 122 | F18: 151 | G18: 273 | H18: 7 | I18: 1353 | J18: 3010 | K18: 1 | L18: 24 | M18: 103553 | N18: 34703 | O18: 79 | P18: 730 | Q18: 25
B19: 657.xz_s | C19: C | D19: 33 | E19: =G19-F19 -> 160 | F19: 193 | G19: 353 | H19: 97 | I19: 561 | J19: 1431 | K19: 8 | L19: 13 | M19: 3666 | N19: 3618 | O19: 149 | P19: 359 | Q19: 18
B23: MAX_NUM_64BIT | C23: =POWER(2, 64) -> 1.8446744e+19
C24: Nodes | I24: Nodes | L24: Edges
B25: Bench marks (C/C++ only) | E25: Total | I25: total | J25: Reachable nodes | K25: Not Reachable nodes | L25: Total | M25: Reachable Edge | N25: Indirect Call | O25: Back Edges | P25: max_num_callees | Q25: MaxID | R25: Sumof(NumCC)
A26: Rate Integer | B26: 500.perlbench_r | H26: 500.perlbench_r | I26: 2362 | J26: 2026 | K26: =I26-J26 -> 336 | L26: 73187 | M26: 71717 | N26: 46433 | O26: 14474 | P26: 326 | Q26: 7.8777715e+65 | R26: 3.7272072e+67
B27: 502.gcc_r | H27: 505.mcf_r | I27: 49 | J27: 46 | K27: =I27-J27 -> 3 | L27: 194 | M27: 184 | N27: 60 | O27: 1 | P27: 2 | Q27: 255 | R27: 309
B28: 505.mcf_r | H28: 508.namd_r | I28: 147 | J28: 118 | K28: =I28-J28 -> 29 | L28: 2501 | M28: 1976 | N28: 83 | O28: 0 | P28: 6 | Q28: 16227 | R28: 16228
B29: 520.omnetpp_r | H29: 510.parest_r | I29: 12849 | J29: 1297 | K29: =I29-J29 -> 11552 | L29: 164154 | M29: 13531 | N29: 3646 | O29: 34 | P29: 83 | Q29: 1595874 | R29: 1613309
B30: 523.xalancbmk_r | H30: 519.lbm_r | I30: 32 | J30: 30 | K30: =I30-J30 -> 2 | L30: 73 | M30: 67 | N30: 0 | O30: 0 | P30: 0 | Q30: 85 | R30: 86
B31: 525.x264_r | H31: 523.xalancbmk_r | I31: 10464 | J31: 1154 | K31: =I31-J31 -> 9310 | L31: 53970 | M31: 6272 | N31: 911 | O31: 341 | P31: 57 | Q31: 19372811709 | R31: 6751104025
B32: 531.deepsjeng_r | H32: 531.deepsjeng_r | I32: 124 | J32: 100 | K32: =I32-J32 -> 24 | L32: 757 | M32: 640 | N32: 0 | O32: 12 | P32: 0 | Q32: 153231 | R32: 206671
B33: 541.leela_r | H33: 538.imagick_r | I33: 2096 | J33: 1072 | K33: =I33-J33 -> 1024 | L33: 32679 | M33: 21980 | N33: 920 | O33: 667 | P33: 21 | Q33: 6.2015217e+24 | R33: 1.1512029e+22
B34: 557.xz_r | H34: 541.leela_r | I34: 343 | J34: 240 | K34: =I34-J34 -> 103 | L34: 2080 | M34: 1135 | N34: 53 | O34: 18 | P34: 1 | Q34: 8864 | R34: 18377
A35: Rate Float | B35: 508.namd_r | H35: 544.nab_r | I35: 255 | J35: 115 | K35: =I35-J35 -> 140 | L35: 2916 | M35: 1342 | N35: 7 | O35: 25 | P35: 1 | Q35: 33328 | R35: 34377
B36: 510.parest_r | H36: 557.xz_r | I36: 364 | J36: 233 | K36: =I36-J36 -> 131 | L36: 2032 | M36: 1260 | N36: 711 | O36: 91 | P36: 27 | Q36: 26403529 | R36: 70022394
B37: 511.povray_r | H37: 600.perlbench_s | I37: 2362 | J37: 2025 | K37: =I37-J37 -> 337 | L37: 74823 | M37: 73347 | N37: 48063 | O37: 14976 | P37: 326 | Q37: 3.702563e+60 | R37: 1.7867623e+67
B38: 519.lbm_r | H38: 605.mcf_s | I38: 49 | J38: 46 | K38: =I38-J38 -> 3 | L38: 194 | M38: 184 | N38: 60 | O38: 1 | P38: 2 | Q38: 255 | R38: 309
B39: 526.blender_r | H39: 619.lbm_s | I39: 43 | J39: 31 | K39: =I39-J39 -> 12 | L39: 94 | M39: 73 | N39: 0 | O39: 0 | P39: 0 | Q39: 95 | R39: 96
B40: 538.imagick_r | H40: 623.xalancbmk_s | I40: 10465 | J40: 1179 | K40: =I40-J40 -> 9286 | L40: 53831 | M40: 6409 | N40: 923 | O40: 330 | P40: 57 | Q40: 28828683857 | R40: 18686859296
B41: 544.nab_r | H41: 631.deepsjeng_s | I41: 124 | J41: 100 | K41: =I41-J41 -> 24 | L41: 757 | M41: 640 | N41: 0 | O41: 12 | P41: 0 | Q41: 153231 | R41: 206671
A42: Speed Integer | B42: 600.perlbench_s | H42: 638.imagick_s | I42: 2295 | J42: 1085 | K42: =I42-J42 -> 1210 | L42: 34437 | M42: 21969 | N42: 737 | O42: 615 | P42: 21 | Q42: 2.3393132e+21 | R42: 1.1958196e+21
B43: 602.gcc_s | H43: 641.leela_s | I43: 343 | J43: 240 | K43: =I43-J43 -> 103 | L43: 2080 | M43: 1135 | N43: 53 | O43: 18 | P43: 1 | Q43: 8864 | R43: 18377
...

Sheet Benchmarks selection (before)
B1: Benchmarks | C1: Language | D1: build bitcode embedded excutable | E1: 2. Callgraph Gen. | F1: 3. Encoding CCW | G1: 4. Embedding CCW to bc | H1: 5. CCW Gen. | I1: 6. CCW Test
A2: Rate Integer | B2: 500.perlbench_r | C2: C | F2: Exceeded 64bit range
B3: 502.gcc_r | C3: C
B4: 505.mcf_r | C4: C | I4: Out of memory. Program aborted
B5: 520.omnetpp_r | C5: C++
B6: 523.xalancbmk_r | C6: C++ | E6: takes hours to finish | H6: takes hours to finish
B7: 525.x264_r | C7: C
B8: 531.deepsjeng_r | C8: C++ | I8: Out of memory. Program aborted
B9: 541.leela_r | C9: C++ | I9: Out of memory. Program aborted
B10: 548.exchange2_r | C10: Fortran
B11: 557.xz_r | C11: C | I11: Out of memory. Program aborted
A12: Rate Float | B12: 503.bwaves_r | C12: Fortran
B13: 507.cactuBSSN_r | C13: C++, C, Fortran
B14: 508.namd_r | C14: C++ | I14: Out of memory. Program aborted
B15: 510.parest_r | C15: C++ | E15: Killed due to OOM
B16: 511.povray_r | C16: C++, C
B17: 519.lbm_r | C17: C | I17: Out of memory. Program aborted
B18: 521.wrf_r | C18: Fortran, C
B19: 526.blender_r | C19: C++, C | E19: Killed due to OOM
B20: 527.cam4_r | C20: Fortran, C
B21: 538.imagick_r | C21: C | F21: Exceeded 64bit range
B22: 544.nab_r | C22: C | I22: Out of memory. Program aborted
B23: 549.fotonik3d_r | C23: Fortran
B24: 554.roms_r | C24: Fortran
A25: Speed Integer | B25: 600.perlbench_s | C25: C | F25: Exceeded 64bit range
B26: 602.gcc_s | C26: C | D26: Symbol multiply defined!
B27: 605.mcf_s | C27: C | I27: Failed (internal crash), Completed w/o DrCCTLib
B28: 620.omnetpp_s | C28: C++ | D28: Assert(i < NumArgs) in Function::getARgs(unsigned i)
B29: 623.xalancbmk_s | C29: C++ | E29: takes hours to finish | H29: takes hours to finish
B30: 625.x264_s | C30: C | D30: Symbol multiply defined!
B31: 631.deepsjeng_s | C31: C++ | I31: Out of memory. Program aborted
B32: 641.leela_s | C32: C++ | I32: Out of memory. Program aborted
B33: 648.exchange2_s | C33: Fortran
B34: 657.xz_s | C34: C | I34: Failed (internal crash), Completed w/o DrCCTLib
A35: Speed Float | B35: 603.bwaves_s | C35: Fortran
B36: 607.cactuBSSN_s | C36: C++, C, Fortran
B37: 619.lbm_s | C37: C | I37: Out of memory. Program aborted
B38: 621.wrf_s | C38: Fortran, C
B39: 627.cam4_s | C39: Fortran, C
B40: 628.pop2_s | C40: Fortran, C
...

Sheet Benchmarks selection (lto)
B1: Benchmarks | C1: Language | D1: 1. Build bitcode embedded excutable extract bitcode (flto) | E1: 2. Callgraph Gen. | F1: 3. Encoding CCW | G1: 4. Embedding CCW to bc | H1: 5. Rebuild exe with bc | I1: 6. CCW Gen. | J1: 7. CCW Test (w/ CCID update)
A2: Rate Integer | B2: 500.perlbench_r | C2: C | D2: Done | E2: Done | F2: Done | G2: CCID Overflow
B3: 502.gcc_r | C3: C | D3: Done | E3: Take too long time | G3: Done
B4: 505.mcf_r | C4: C | D4: Done | E4: Done | F4: Done
B5: 520.omnetpp_r | C5: C++ | D5: Done | E5: Function.h:781: llvm::Argument* llvm::Function::getArg(unsigned int) const: Assertion `i < NumArgs && "getArg() out of range!"' failed.
B6: 523.xalancbmk_r | C6: C++ | D6: Done | E6: Done | F6: Done | G6: Done
B7: 525.x264_r | C7: C | D7: Done | E7: Done | F7: Done | G7: Done
B8: 531.deepsjeng_r | C8: C++ | D8: Done | E8: Done | F8: Done | G8: Done
B9: 541.leela_r | C9: C++ | D9: Done | E9: Done | F9: Done | G9: Done | H9: Many undefined reference
B10: 548.exchange2_r | C10: Fortran
B11: 557.xz_r | C11: C | D11: Done | E11: Done | F11: Done | G11: Done
A12: Rate Float | B12: 503.bwaves_r | C12: Fortran
B13: 507.cactuBSSN_r | C13: C++, C, Fortran
B14: 508.namd_r | C14: C++ | D14: Done | E14: Done | F14: Done | G14: Done
B15: 510.parest_r | C15: C++ | D15: Done | E15: Done | F15: Done | G15: Done
B16: 511.povray_r | C16: C++, C | D16: Done | E16: Function.h:781: llvm::Argument* llvm::Function::getArg(unsigned int) const: Assertion `i < NumArgs && "getArg() out of range!"' failed.
B17: 519.lbm_r | C17: C | D17: Done | E17: Done | F17: Done | G17: Done
B18: 521.wrf_r | C18: Fortran, C
B19: 526.blender_r | C19: C++, C | D19: Done | E19: Take too long time
B20: 527.cam4_r | C20: Fortran, C
B21: 538.imagick_r | C21: C | D21: Done | E21: Take too long time
B22: 544.nab_r | C22: C | D22: Done | E22: Done | F22: Done | G22: Done
B23: 549.fotonik3d_r | C23: Fortran
B24: 554.roms_r | C24: Fortran
A25: Speed Integer | B25: 600.perlbench_s | C25: C | D25: Done | E25: Done | F25: Done
B26: 602.gcc_s | C26: C | D26: Done | E26: Take too long time
B27: 605.mcf_s | C27: C | D27: Done | E27: Done | F27: Done
B28: 620.omnetpp_s | C28: C++ | D28: Done | E28: Function.h:781: llvm::Argument* llvm::Function::getArg(unsigned int) const: Assertion `i < NumArgs && "getArg() out of range!"' failed.
B29: 623.xalancbmk_s | C29: C++ | D29: Done | E29: Done | F29: Done
B30: 625.x264_s | C30: C | D30: Done | E30: Done | F30: Done
B31: 631.deepsjeng_s | C31: C++ | D31: Done | E31: Done | F31: Done
B32: 641.leela_s | C32: C++ | D32: Done | E32: Done | F32: Done | H32: Many undefined reference
B33: 648.exchange2_s | C33: Fortran
B34: 657.xz_s | C34: C | D34: Done | E34: Done | F34: Done | J34: Running
A35: Speed Float | B35: 603.bwaves_s | C35: Fortran
B36: 607.cactuBSSN_s | C36: C++, C, Fortran
B37: 619.lbm_s | C37: C | D37: Done | E37: Done | F37: Done | J37: Running
B38: 621.wrf_s | C38: Fortran, C
B39: 627.cam4_s | C39: Fortran, C
B40: 628.pop2_s | C40: Fortran, C
...

Sheet Runtime
A1: bitcode before lto | B1: on real machine (HPCServer) | C1: drclient_empty | D1: drclient_callret_overhead_test | E1: drclient_ccw_test(ver1) | F1: drclient_ccw_test (free res after use) | G1: drclient_ccw_test(ver2) | H1: drcctlib_callret_overhead_test | I1: SPEED UP (drcctlib/DCCE)
A2: 100.test-pcce-fig-4 | B2: 5 | C2: 55 | D2: 108 | E2: 1224 | F2: 35724 | G2: 45 | H2: 290 | I2: =H2/G2 -> 6.4444444
A3: 101.test-pcce-fig-5a | B3: 9 | C3: 96 | D3: 193 | E3: 1259 | F3: 33996 | G3: 46 | H3: 278 | I3: =H3/G3 -> 6.0434783
A4: 102.test-indirect-call | B4: 9 | C4: 65 | D4: 123 | E4: 1251 | F4: 34060 | G4: 57 | H4: 255 | I4: =H4/G4 -> 4.4736842
A5: 103.test-libc-nostatic-nodebug | B5: 8 | C5: 58 | D5: 136 | E5: 1265 | F5: 34863 | G5: 48 | H5: 283 | I5: =H5/G5 -> 5.8958333
A6: 103.test-libc-static-nodebug | B6: 5 | C6: 65 | D6: 176 | E6: 1287 | F6: 34939 | G6: 110 | H6: 226 | I6: =H6/G6 -> 2.0545455
A7: 103.test-libc-static-debug | B7: 8 | C7: 55 | D7: 112 | E7: 1271 | F7: 35037 | G7: 47 | H7: 301 | I7: =H7/G7 -> 6.4042553
A8: 104.test-backedge | B8: 8 | C8: 57 | D8: 176 | E8: 1296 | F8: 34544 | G8: 48 | H8: 223 | I8: =H8/G8 -> 4.6458333
A9: 105.test-functionname | B9: 4 | C9: 58 | D9: 103 | E9: 1335 | F9: 36295 | G9: 75 | H9: 288 | I9: =H9/G9 -> 3.84
A10: 106.test-machinecode | B10: 8 | C10: 58 | D10: 183 | E10: 1360 | F10: 34669 | G10: 45 | H10: 262 | I10: =H10/G10 -> 5.8222222
A11: 108.test-mleak | B11: 3390 | C11: 14370 | D11: 24984 | E11: Out of memory | F11: Out of memory | G11: 303244 | H11: 321950 | I11: =H11/G11 -> 1.0616863
A12: 109.test-matadd | B12: 60 | C12: 310 | D12: 549 | E12: 9203 | F12: 989686 | G12: 698 | H12: 991 | I12: =H12/G12 -> 1.4197708
A13: 505.mcf_r | B13: =17*60000+32818 -> 1052818 | C13: 2031012 | D13: 2659960 | E13: Out of memory | F13: takes more than one day | G13: 7253092 | H13: 9994200 | I13: =H13/G13 -> 1.3779227
A14: 508.namd_r | B14: =13*60000+36693 -> 816693 | C14: 1550110 | D14: 1637836 | E14: Out of memory | F14: takes more than one day | H14: 2261877
A15: 519.lbm_r | B15: =9*60000+21555 -> 561555 | C15: 1357122 | D15: 1467185 | E15: Out of memory | F15: takes more than one day | G15: 528075 | H15: 1788415 | I15: =H15/G15 -> 3.3866686
A16: 531.deepsjeng_r | B16: =13*60000+36483 -> 816483 | C16: 1967186 | D16: 2954897 | E16: Out of memory | F16: Out of memory | G16: 2989952 | H16: Preallocated IPNodes exhauste
A17: 541.leela_r | B17: =16*60000+46630 -> 1006630 | C17: 2276682 | D17: 3537412 | E17: Out of memory | F17: takes more than one day | H17: 24130564
A18: 544.nab_r | B18: =22*60000+17959 -> 1337959 | C18: 2226512 | D18: 2754826 | E18: Out of memory | F18: takes more than one day | G18: 3721130 | H18: 11302430 | I18: =H18/G18 -> 3.037365
A19: 557.xz_r | B19: =5*60000+42885 -> 342885 | C19: 1045588 | D19: 1072676 | E19: Out of memory | F19: takes more than one day | G19: 337705 | H19: 1641335 | I19: =H19/G19 -> 4.8602627
A20: 605.mcf_s | B20: =35*60000+53501 -> 2153501 | C20: 3330912 | D20: 4458237 | E20: Out of memory | F20: takes more than one day | G20: 15155255 | H20: 17469716 | I20: =H20/G20 -> 1.1527167
A21: 619.lbm_s | B21: =4*60000+31695 -> 271695 | C21: 930676 | D21: 1011368 | E21: Out of memory | F21: takes more than one day | G21: 733558 | H21: 1178330 | I21: =H21/G21 -> 1.6063215
A22: 631.deepsjeng_s | B22: =17+60000+34340 -> 94357 | C22: 2202799 | D22: 3511199 | E22: Out of memory | F22: Out of memory | G22: 100878 | H22: Preallocated IPNodes exhauste
A23: 641.leela_s | B23: =16*60000+44444 -> 1004444 | C23: 2229043 | D23: 3458414 | E23: Out of memory | F23: takes more than one day | H23: 24391148
A24: 644.nab_s | B24: =10*60000+37591 -> 637591 | C24: 1210424 | D24: 1431238 | E24: Out of memory | F24: takes more than one day | G24: 1777054 | H24: 4835889 | I24: =H24/G24 -> 2.7212955
A25: 657.xz_s | B25: =10*60000+4055 -> 604055 | C25: 1348431 | D25: 1493717 | E25: Out of memory | F25: takes more than one day | G25: 438221 | H25: 2015262 | I25: =H25/G25 -> 4.5987344
I26: =GEOMEAN(I13:I25) -> 2.5141456 | J26: <-- only SPEC
B32: on real machine (HPCServer) | C32: drclient_empty | D32: drclient_callret_overhead_test | E32: drclient_ccw_test | F32: drcctlib_callret_overhead_test
A33: 505.mcf_r | B33: =17*60000+32818 -> 1052818 | C33: 2031012 | D33: 2659960 | F33: 9994200
A34: 508.namd_r | B34: =13*60000+36693 -> 816693 | C34: 1550110 | D34: 1637836 | F34: 2261877
A35: 519.lbm_r | B35: =9*60000+21555 -> 561555 | C35: 1357122 | D35: 1467185 | F35: 1788415
A36: 531.deepsjeng_r | B36: =13*60000+36483 -> 816483 | C36: 1967186 | D36: 2954897 | F36: Preallocated IPNodes exhauste
A37: 541.leela_r | B37: =16*60000+46630 -> 1006630 | C37: 2276682 | D37: 3537412 | F37: 24130564
A38: 544.nab_r | B38: =22*60000+17959 -> 1337959 | C38: 2226512 | D38: 2754826 | F38: 11302430
A39: 557.xz_r | B39: =5*60000+42885 -> 342885 | C39: 1045588 | D39: 1072676 | F39: 1641335
A40: 605.mcf_s | B40: =35*60000+53501 -> 2153501 | C40: 3330912 | D40: 4458237 | F40: 17469716
A41: 619.lbm_s | B41: =4*60000+31695 -> 271695 | C41: 930676 | D41: 1011368 | F41: 1178330
A42: 631.deepsjeng_s | B42: =17+60000+34340 -> 94357 | C42: 2202799 | D42: 3511199 | F42: Preallocated IPNodes exhauste
A43: 641.leela_s | B43: =16*60000+44444 -> 1004444 | C43: 2229043 | D43: 3458414 | F43: 24391148
A44: 644.nab_s | B44: =10*60000+37591 -> 637591 | C44: 1210424 | D44: 1431238 | F44: 4835889
A45: 657.xz_s | B45: =10*60000+4055 -> 604055 | C45: 1348431 | D45: 1493717 | F45: 2015262
...

Sheet Call Graph Stat (lto,-O3,-nog)
D1: SVF | L1: DCCE | M1: PCCE | N1: Valence
D2: Nodes | K2: Cyclic Edges | L2: MaxID | M2: Sum(numCC) | N2: Nodes | O2: Edges | P2: Cyclick Edges
B3: Language | C3: KLOC | D3: Reachable nodes | E3: Not Reachable | F3: Total | G3: Indirect Calls | H3: Reachable Edge | I3: Total | J3: max_num_callees
A4: 508.namd_r | B4: C++ | C4: 8 | D4: =F4-E4 -> 118 | E4: 29 | F4: 147 | G4: 83 | H4: 1976 | I4: 2501 | J4: 6 | K4: 0 | L4: 16227 | M4: 16228 | N4: 61 | O4: 553 | P4: 0
A5: 510.parest_r | B5: C++ | C5: 427 | N5: 1315 | O5: 15080 | P5: 200
A6: 511.povray_r | B6: C++,C | C6: 170 | N6: 519 | O6: 825 | P6: 2380
A7: 600.perlbench_s | B7: C | C7: 362 | D7: =F7-E7 -> 2019 | E7: 342 | F7: 2361 | G7: 44557 | H7: 68965 | I7: 70468 | J7: 326 | K7: 11699 | L7: 3.0698198e+81 | M7: 1.0819829e+65
A8: 602.gcc_s | B8: C | C8: 1304 | N8: 19011 | O8: 131388 | P8: 28330
A9: 605.mcf_s | B9: C | C9: 3 | D9: =F9-E9 -> 46 | E9: 4 | F9: 50 | G9: 60 | H9: 179 | I9: 189 | J9: 2 | K9: 1 | L9: 274 | M9: 304 | N9: 32 | O9: 126 | P9: 1
A10: 607.cactuBSSN_s | B10: C++,C,Fortran | C10: 257 | N10: 1048 | O10: 22820 | P10: 67
A11: 619.lbm_s | B11: C | C11: 1 | D11: =F11-E11 -> 31 | E11: 12 | F11: 43 | G11: 0 | H11: 73 | I11: 94 | J11: 0 | K11: 0 | L11: 95 | M11: 96 | N11: 17 | O11: 27 | P11: 0
A12: 620.omnetpp_s | B12: C++ | C12: 134
A13: 623.xalancbmk_s | B13: C++ | C13: 520 | D13: =F13-E13 -> 1125 | E13: 9351 | F13: 10476 | G13: 6914 | H13: 6245 | I13: 54332 | J13: 57 | K13: 327 | L13: 1.2589179e+16 | M13: 19894985784 | N13: 4055 | O13: 22848 | P13: 1566
A14: 625.x264_s | B14: C | C14: 96 | D14: =F14-E14 -> 519 | E14: 5 | F14: 524 | G14: 17731 | H14: 21213 | I14: 21228 | J14: 36 | K14: 1 | L14: 21350563 | M14: 21368452 | N14: 367 | O14: 2318 | P14: 2
A15: 631.deepsjeng_s | B15: C++ | C15: 10 | D15: =F15-E15 -> 100 | E15: 24 | F15: 124 | G15: 0 | H15: 642 | I15: 759 | J15: 0 | K15: 12 | L15: 31931071 | M15: 219943 | N15: 87 | O15: 573 | P15: 12
A16: 638.imagick_s | B16: C | C16: 259 | D16: =F16-E16 -> 1069 | E16: 1219 | F16: 2288 | G16: 545 | H16: 21560 | I16: 34003 | J16: 19 | K16: 854 | L16: 1.6332216e+47 | M16: 2.5614589e+20 | N16: 915 | O16: 18864 | P16: 524
A17: 641.leela_s | B17: C++ | C17: 21 | D17: =F17-E17 -> 242 | E17: 104 | F17: 346 | G17: 78 | H17: 1122 | I17: 2072 | J17: 1 | K17: 18 | L17: 22464 | M17: 17574 | N17: 204 | O17: 1013 | P17: 23
A18: 644.nab_s | B18: C | C18: 24 | D18: =F18-E18 -> 122 | E18: 151 | F18: 273 | G18: 7 | H18: 1353 | I18: 3010 | J18: 1 | K18: 24 | L18: 103553 | M18: 34703 | N18: 79 | O18: 730 | P18: 25
A19: 657.xz_s | B19: C | C19: 33 | D19: =F19-E19 -> 160 | E19: 193 | F19: 353 | G19: 97 | H19: 561 | I19: 1431 | J19: 8 | K19: 13 | L19: 3666 | M19: 3618 | N19: 149 | O19: 359 | P19: 18
A23: MAX_ID | B23: =POWER(2, 64) -> 1.8446744e+19
B24: Nodes | E24: Edges
B25: total | C25: Reachable nodes | D25: Not Reachable nodes | E25: Total | F25: Reachable Edge | G25: Indirect Call | H25: Back Edges | I25: max_num_callees | J25: MaxID | K25: Sumof(NumCC)
A26: 500.perlbench_r | B26: 1636 | C26: 1630 | D26: =B26-C26 -> 6 | E26: 75941 | F26: 75932 | G26: 50000 | H26: 17475 | I26: 325 | J26: 2.8342649e+66 | K26: 5.3748395e+73
A27: 505.mcf_r | B27: 25 | C27: 25 | D27: =B27-C27 -> 0 | E27: 137 | F27: 137 | G27: 48 | H27: 1 | I27: 2 | J27: 188 | K27: 238
A28: 508.namd_r | B28: 102 | C28: 89 | D28: =B28-C28 -> 13 | E28: 2067 | F28: 1952 | G28: 66 | H28: 0 | I28: 6 | J28: 16077 | K28: 16078
A29: 510.parest_r | B29: 2251 | C29: 735 | D29: =B29-C29 -> 1516 | E29: 56101 | F29: 15716 | G29: 6851 | H29: 35 | I29: 78 | J29: 181552343 | K29: 199105724
A30: 519.lbm_r | B30: 19 | C30: 19 | D30: =B30-C30 -> 0 | E30: 56 | F30: 56 | G30: 0 | H30: 0 | I30: 0 | J30: 70 | K30: 71
A31: 523.xalancbmk_r | B31: 5441 | C31: 708 | D31: =B31-C31 -> 4733 | E31: 33617 | F31: 4899 | G31: 60 | H31: 383 | I31: 56 | J31: 6887516747 | K31: 7915966584
A32: 525.x264_r | B32: 395 | C32: 394 | D32: =B32-C32 -> 1 | E32: 21315 | F32: 21313 | G32: 17911 | H32: 1 | I32: 36 | J32: 18929164 | K32: 18945454
A33: 531.deepsjeng_r | B33: 39 | C33: 39 | D33: =B33-C33 -> 0 | E33: 251 | F33: 251 | G33: 0 | H33: 12 | I33: 0 | J33: 13719 | K33: 18155
A34: 538.imagick_r | B34: 534 | C34: 522 | D34: =B34-C34 -> 12 | E34: 19812 | F34: 19777 | G34: 1479 | H34: 945 | I34: 16 | J34: 4.1014078e+23 | K34: 1.1075872e+19
A35: 541.leela_r | B35: 120 | C35: 111 | D35: =B35-C35 -> 9 | E35: 783 | F35: 742 | G35: 0 | H35: 18 | I35: 0 | J35: 4548 | K35: 8884
A36: 544.nab_r | B36: 82 | C36: 81 | D36: =B36-C36 -> 1 | E36: 1174 | F36: 1151 | G36: 0 | H36: 22 | I36: 0 | J36: 29278 | K36: 30245
A37: 557.xz_r | B37: 139 | C37: 137 | D37: =B37-C37 -> 2 | E37: 1982 | F37: 1980 | G37: 1651 | H37: 213 | I37: 22 | J37: 171336155084 | K37: 142454315812
... A47: 657.xz_s | B47: 151 | C47: 136 | D47: =B47-C47 -> 15 | E47: 2042 | F47: 1900 | G47: 1561 | H47: 225 | I47: 22 | J47: 343806150166 | K47: 42612142025
A53: before lto, -O3, -nog | B53: Nodes | E53: Edges
B54: total | C54: Reachable nodes | D54: Not Reachable nodes | E54: Total | F54: Reachable Edge | G54: Indirect Call | H54: Back Edges | I54: max_num_callees | J54: MaxID | K54: Sumof(NumCC)
A55: 500.perlbench_r | B55: 2362 | C55: 2026 | D55: =B55-C55 -> 336 | E55: 73187 | F55: 71717 | G55: 46433 | H55: 14474 | I55: 326 | J55: 7.8777715e+65 | K55: 3.7272072e+67
A56: 505.mcf_r | B56: 49 | C56: 46 | D56: =B56-C56 -> 3 | E56: 194 | F56: 184 | G56: 60 | H56: 1 | I56: 2 | J56: 255 | K56: 309
A57: 508.namd_r | B57: 147 | C57: 118 | D57: =B57-C57 -> 29 | E57: 2501 | F57: 1976 | G57: 83 | H57: 0 | I57: 6 | J57: 16227 | K57: 16228
...

Sheet Bench status (lto,-O3, -nog)
B1: Benchmarks | C1: Language | D1: 1. Build bitcode embedded excutable extract bitcode (flto) | E1: 2. Callgraph Gen. | F1: 3. Encoding CCW | G1: 4. Embedding CCW to bc | H1: 5. Rebuild exe with bc | I1: 6. CCW Gen. | J1: 7. CCW Test (w/ CCID update)
A2: Rate Integer | B2: 500.perlbench_r | C2: C | D2: Done | E2: Done | F2: MAXID Overflow
B3: 502.gcc_r | C3: C | D3: Done | E3: OOM
B4: 505.mcf_r | C4: C | D4: Done | E4: Done | F4: Done | G4: Done | H4: Done | I4: Done
B5: 520.omnetpp_r | C5: C++ | D5: Done | E5: Assertion in Function::getArg
B6: 523.xalancbmk_r | C6: C++ | D6: Done | E6: Done | F6: Done | G6: Done | H6: Done | I6: Done
B7: 525.x264_r | C7: C | D7: Done | E7: Done | F7: Done | G7: Done | H7: Done | I7: Done
B8: 531.deepsjeng_r | C8: C++ | D8: Done | E8: Done | F8: Done | G8: Done | H8: Done | I8: Done
B9: 541.leela_r | C9: C++ | D9: Done | E9: Done | F9: Done | G9: Done | H9: Done | I9: Done
B10: 548.exchange2_r | C10: Fortran
B11: 557.xz_r | C11: C | D11: Done | E11: Done | F11: Done | G11: Done | H11: Done | I11: Done
A12: Rate Float | B12: 503.bwaves_r | C12: Fortran
B13: 507.cactuBSSN_r | C13: C++, C, Fortran
B14: 508.namd_r | C14: C++ | D14: Done | E14: Done | F14: Done | G14: Done | H14: Done | I14: Done
B15: 510.parest_r | C15: C++ | D15: Done | E15: Done | F15: Done | G15: Done | H15: Done | I15: Done
B16: 511.povray_r | C16: C++, C | D16: Done | E16: Assertion in Function::getArg
B17: 519.lbm_r | C17: C | D17: Done | E17: Done | F17: Done | G17: Done | H17: Done | I17: Done
B18: 521.wrf_r | C18: Fortran, C
B19: 526.blender_r | C19: C++, C | D19: Done | E19: OOM
B20: 527.cam4_r | C20: Fortran, C
B21: 538.imagick_r | C21: C | D21: Done | E21: Done | F21: MAXID Overflow
B22: 544.nab_r | C22: C | D22: Done | E22: Done | F22: Done | G22: Done | H22: Done | I22: Done
B23: 549.fotonik3d_r | C23: Fortran
B24: 554.roms_r | C24: Fortran
A25: Speed Integer | B25: 600.perlbench_s | C25: C | D25: Done | E25: Done | F25: MAXID Overflow
B26: 602.gcc_s | C26: C | D26: Done | E26: OOM
B27: 605.mcf_s | C27: C | D27: Done | E27: Done | F27: Done | G27: Done | H27: Done | I27: Done
B28: 620.omnetpp_s | C28: C++ | D28: Done | E28: Assertion in Function::getArg
B29: 623.xalancbmk_s | C29: C++ | D29: Done | E29: Done | F29: Done | G29: Done | H29: Done | I29: Done
B30: 625.x264_s | C30: C | D30: Done | E30: Done | F30: Done | G30: Done | H30: Done | I30: Done
B31: 631.deepsjeng_s | C31: C++ | D31: Done | E31: Done | F31: Done | G31: Done | H31: Done | I31: Done
B32: 641.leela_s | C32: C++ | D32: Done | E32: Done | F32: Done | G32: Done | H32: Done | I32: Done
B33: 648.exchange2_s | C33: Fortran
B34: 657.xz_s | C34: C | D34: Done | E34: Done | F34: Done | G34: Done | H34: Done | I34: Done
A35: Speed Float | B35: 603.bwaves_s | C35: Fortran
B36: 607.cactuBSSN_s | C36: C++, C, Fortran
B37: 619.lbm_s | C37: C | D37: Done | E37: Done | F37: Done | G37: Done | H37: Done | I37: Done
B38: 621.wrf_s | C38: Fortran, C
B39: 627.cam4_s | C39: Fortran, C
B40: 628.pop2_s | C40: Fortran, C
...

Sheet Runtime(desktop)
B1: on real machine (HPCServer) | C1: drclient_empty | D1: drclient_callret_overhead_test | E1: drclient_ccw_test | F1: drcctlib_callret_overhead_test
A2: 505.mcf_r | B2: 330101 | C2: 390455 | D2: 680484 | E2: 1592955 | F2: 3773930
A3: 508.namd_r | B3: 247041 | C3: 249922 | D3: 256366 | E3: 286219 | F3: 363759
A4: 510.parest_r | B4: 396815 | C4: 418528 | D4: 505582 | E4: 700581 | F4: 1202613
A5: 519.lbm_r | B5: 244328 | C5: 243024 | D5: 248920 | E5: 251917 | F5: 251619
A6: 523.xalancbmk_r | B6: 297593 | C6: 347461 | D6: 503105 | E6: 896709 | F6: 2006719
A7: 525.x264_r | B7: 112919 | C7: 137956 | D7: 171263 | E7: 312446 | F7: 715470
A8: 531.deepsjeng_r | B8: 235714 | C8: 304029 | D8: 362594 | F8: OOM
A9: 541.leela_r | B9: 383049 | C9: 463092 | D9: 547618 | E9: 1019098 | F9: 2550537
A10: 557.xz_r | B10: 179200 | C10: 128512 | D10: 130056 | E10: 142310 | F10: 181280
A11: 605.mcf_s | B11: 663078 | C11: 787314 | D11: 1349722 | E11: 3138151 | F11: 7371063
A12: 619.lbm_s | B12: 1158885 | C12: 1159928 | D12: 1163304 | E12: 1160786 | F12: 1164322
A13: 623.xalancbmk_s | B13: 293066 | C13: 347659 | D13: 494922 | E13: 904347 | F13: 2040430
A14: 625.x264_s | B14: 112343 | C14: 136900 | D14: 171680 | E14: 312136 | F14: 713424
A15: 631.deepsjeng_s | B15: 292945 | C15: 371736 | D15: 442455 | F15: OOM
A16: 641.leela_s | B16: 382069 | C16: 461747 | D16: 549074 | E16: 1026999 | F16: 2530139
A17: 657.xz_s | B17: 318305 | C17: 323084 | D17: 330269 | E17: 374908 | F17: 477259
B21: drclient_empty | C21: drclient_ccw_test | D21: drcctlib_callret_overhead_test
A22: 505.mcf_r | B22: 389783 | C22: 2010172 | D22: 3773642
A23: 508.namd_r | B23: 251150 | C23: 484684 | D23: 364713
A24: 510.parest_r | B24: 1043725 | C24: 1475773 | D24: 1851488
A25: 519.lbm_r | B25: 249042 | C25: 416744 | D25: 248431
A26: 523.xalancbmk_r | B26: 347060 | C26: 1463177 | D26: 2006009
A27: 525.x264_r | B27: 136507 | C27: 638162 | D27: 723438
A28: 541.leela_r | B28: 461236 | C28: 1305772 | D28: 2522744
A29: 557.xz_r | B29: 125468 | C29: 248155 | D29: 181604
A30: 605.mcf_s | B30: 788407 | C30: 3920403 | D30: 7329264
A31: 619.lbm_s | B31: 1159042 | C31: 1186949 | D31: 1190759
A32: 623.xalancbmk_s | B32: 346111 | C32: 1473093 | D32: 2003160
A33: 625.x264_s | B33: 136339 | C33: 638205 | D33: 715783
... A35: 657.xz_s | B35: 325694 | C35: 767217 | D35: 481545
B40: drclient_empty | C40: drclient_ccw_test | D40: drcctlib_callret_overhead_test | E40: DCCE vs. DrCCTLib
A41: 505.mcf_r | B41: =B22/$B22 -> 1 | C41: =C22/$B22 -> 5.1571567 | D41: =D22/$B22 -> 9.681392 | E41: =D41/C41 -> 1.8772732
A42: 508.namd_r | B42: =B23/$B23 -> 1 | C42: =C23/$B23 -> 1.9298587 | D42: =D23/$B23 -> 1.452172 | E42: =D42/C42 -> 0.75247584
A43: 510.parest_r | B43: =B24/$B24 -> 1 | C43: =C24/$B24 -> 1.4139481 | D43: =D24/$B24 -> 1.7739232 | E43: =D43/C43 -> 1.2545886
A44: 519.lbm_r | B44: =B25/$B25 -> 1 | C44: =C25/$B25 -> 1.6733884 | D44: =D25/$B25 -> 0.9975466 | E44: =D44/C44 -> 0.59612376
A45: 523.xalancbmk_r | B45: =B26/$B26 -> 1 | C45: =C26/$B26 -> 4.2159194 | D45: =D26/$B26 -> 5.7800063 | E45: =D45/C45 -> 1.3709954
A46: 525.x264_r | B46: =B27/$B27 -> 1 | C46: =C27/$B27 -> 4.6749397 | D46: =D27/$B27 -> 5.2996403 | E46: =D46/C46 -> 1.1336275
A47: 541.leela_r | B47: =B28/$B28 -> 1 | C47: =C28/$B28 -> 2.8310279 | D47: =D28/$B28 -> 5.4695297 | E47: =D47/C47 -> 1.9319943
A48: 557.xz_r | B48: =B29/$B29 -> 1 | C48: =C29/$B29 -> 1.977835 | D48: =D29/$B29 -> 1.4474129 | E48: =D48/C48 -> 0.73181681
...

Sheet Static Dynamic Characteristics
C1: Static
B2: Benchmarks | C2: Nodes | F2: Edges | K2: Max CCID | N2: #total calls | O2: Dynamic Max CCID | P2: Stack Depth
C3: total | D3: Reachable nodes | E3: Not Reachable nodes | F3: Total | G3: Reachable Edge | H3: Indirect Call | I3: max_num_callees | J3: Back Edges | K3: DCCE | L3: PCCE | M3: Valence
A4: SPEC 2017 | B4: 500.perlbench_r | C4: 2362 | D4: 2026 | E4: =C4-D4 -> 336 | F4: 73187 | G4: 71717 | H4: 46433 | I4: 326 | J4: 14474 | K4: 7.8777715e+65
B5: 505.mcf_r | C5: 49 | D5: 46 | E5: =C5-D5 -> 3 | F5: 194 | G5: 184 | H5: 60 | I5: 2 | J5: 1 | K5: 255
B6: 508.namd_r | C6: 147 | D6: 118 | E6: =C6-D6 -> 29 | F6: 2501 | G6: 1976 | H6: 83 | I6: 6 | J6: 0 | K6: 16227
B7: 510.parest_r | C7: 12849 | D7: 1297 | E7: =C7-D7 -> 11552 | F7: 164154 | G7: 13531 | H7: 3646 | I7: 83 | J7: 34 | K7: 1595874
B8: 519.lbm_r | C8: 32 | D8: 30 | E8: =C8-D8 -> 2 | F8: 73 | G8: 67 | H8: 0 | I8: 0 | J8: 0 | K8: 85
B9: 523.xalancbmk_r | C9: 10464 | D9: 1154 | E9: =C9-D9 -> 9310 | F9: 53970 | G9: 6272 | H9: 911 | I9: 57 | J9: 341 | K9: 19372811709
B10: 531.deepsjeng_r | C10: 124 | D10: 100 | E10: =C10-D10 -> 24 | F10: 757 | G10: 640 | H10: 0 | I10: 0 | J10: 12 | K10: 153231
B11: 538.imagick_r | C11: 2096 | D11: 1072 | E11: =C11-D11 -> 1024 | F11: 32679 | G11: 21980 | H11: 920 | I11: 21 | J11: 667 | K11: 6.2015217e+24 | Q11: =POWER(2,64) -> 1.8446744e+19
B12: 541.leela_r | C12: 343 | D12: 240 | E12: =C12-D12 -> 103 | F12: 2080 | G12: 1135 | H12: 53 | I12: 1 | J12: 18 | K12: 8864
B13: 544.nab_r | C13: 255 | D13: 115 | E13: =C13-D13 -> 140 | F13: 2916 | G13: 1342 | H13: 7 | I13: 1 | J13: 25 | K13: 33328
B14: 557.xz_r | C14: 364 | D14: 233 | E14: =C14-D14 -> 131 | F14: 2032 | G14: 1260 | H14: 711 | I14: 27 | J14: 91 | K14: 26403529
B15: 600.perlbench_s | C15: 2362 | D15: 2025 | E15: =C15-D15 -> 337 | F15: 74823 | G15: 73347 | H15: 48063 | I15: 326 | J15: 14976 | K15: 3.702563e+60
B16: 605.mcf_s | C16: 49 | D16: 46 | E16: =C16-D16 -> 3 | F16: 194 | G16: 184 | H16: 60 | I16: 2 | J16: 1 | K16: 255
B17: 619.lbm_s | C17: 43 | D17: 31 | E17: =C17-D17 -> 12 | F17: 94 | G17: 73 | H17: 0 | I17: 0 | J17: 0 | K17: 95
B18: 623.xalancbmk_s | C18: 10465 | D18: 1179 | E18: =C18-D18 -> 9286 | F18: 53831 | G18: 6409 | H18: 923 | I18: 57 | J18: 330 | K18: 28828683857
B19: 631.deepsjeng_s | C19: 124 | D19: 100 | E19: =C19-D19 -> 24 | F19: 757 | G19: 640 | H19: 0 | I19: 0 | J19: 12 | K19: 153231
B20: 638.imagick_s | C20: 2295 | D20: 1085 | E20: =C20-D20 -> 1210 | F20: 34437 | G20: 21969 | H20: 737 | I20: 21 | J20: 615 | K20: 2.3393132e+21
B21: 641.leela_s | C21: 343 | D21: 240 | E21: =C21-D21 -> 103 | F21: 2080 | G21: 1135 | H21: 53 | I21: 1 | J21: 18 | K21: 8864
B22: 644.nab_s | C22: 273 | D22: 122 | E22: =C22-D22 -> 151 | F22: 3014 | G22: 1358 | H22: 7 | I22: 1 | J22: 24 | K22: 33658
B23: 657.xz_s | C23: 375 | D23: 232 | E23: =C23-D23 -> 143 | F23: 2090 | G23: 1255 | H23: 681 | I23: 27 | J23: 77 | K23: 13491326
A24: Splash-3 | B24: 701.BARNES | C24: 73 | D24: 73 | E24: =C24-D24 -> 0 | F24: 270 | G24: 270 | H24: 0 | I24: 0 | J24: 2 | K24: 495 | N24: 32328363 | O24: 3761 | P24: 5
B25: 702.CHOLESKY | C25: 155 | D25: 155 | E25: =C25-D25 -> 0 | F25: 536 | G25: 536 | H25: 0 | I25: 0 | J25: 4 | K25: 4819 | N25: 2025479 | O25: 13740 | P25: 5
B26: 703.FFT | C26: 39 | D26: 39 | E26: =C26-D26 -> 0 | F26: 187 | G26: 187 | H26: 0 | I26: 0 | J26: 0 | K26: 373 | N26: 662506 | O26: 10677 | P26: 5
B27: 704.FMM | C27: 115 | D27: 115 | E27: =C27-D27 -> 0 | F27: 542 | G27: 542 | H27: 38 | I27: 7 | J27: 8 | K27: 14473 | N27: 4130829 | O27: 6939 | P27: 5
B28: 705.LU-CB | C28: 39 | D28: 39 | E28: =C28-D28 -> 0 | F28: 160 | G28: 160 | H28: 0 | I28: 0 | J28: 0 | K28: 221 | N28: 1503067565 | O28: 2497 | P28: 5
B29: 706.LU-NCB | C29: 36 | D29: 36 | E29: =C29-D29 -> 0 | F29: 148 | G29: 148 | H29: 0 | I29: 0 | J29: 0 | K29: 208 | N29: 1502936468 | O29: 2461 | P29: 5
B30: 707.OCEAN-CP | C30: 43 | D30: 43 | E30: =C30-D30 -> 0 | F30: 339 | G30: 339 | H30: 0 | I30: 0 | J30: 0 | K30: 612 | N30: 16808171 | O30: 5376 | P30: 5
B31: 708.OCEAN-NCP | C31: 35 | D31: 35 | E31: =C31-D31 -> 0 | F31: 265 | G31: 265 | H31: 0 | I31: 0 | J31: 0 | K31: 495 | N31: 37601 | O31: 4925 | P31: 5
B32: 709.RADIOSITY | N32: 43806613 | O32: 3628705 | P32: 5
B33: 710.RADIX | C33: 205 | D33: 150 | E33: =C33-D33 -> 55 | F33: 835 | G33: 613 | H33: 16 | I33: 7 | J33: 30 | K33: 315092 | N33: 368195465 | O33: 2535 | P33: 5
B34: 713.WATER-NSQUARED | C34: 42 | D34: 42 | E34: =C34-D34 -> 0 | F34: 221 | G34: 221 | H34: 0 | I34: 0 | J34: 0 | K34: 394 | N34: 161893449 | O34: 4630 | P34: 5
B35: 714.WATER-SPATIAL | C35: 42 | D35: 42 | E35: =C35-D35 -> 0 | F35: 234 | G35: 234 | H35: 0 | I35: 0 | J35: 0 | K35: 397 | N35: 27416376 | O35: 4958 | P35: 5
C37: Static barriers | D37: Dynamic barriers
D38: 8 threads | E38: 16 threads
B39: 701.BARNES | C39: 6 | D39: 136 | E39: 272 | P39: 4208
B40: 702.CHOLESKY | C40: 4 | D40: 32 | E40: 64 | P40: 48 | Q40: 4256
B41: 703.FFT | C41: 7 | D41: 56 | E41: 112 | P41: 8560 | Q41: 8608
...

Sheet Static_Overhead_SPEC2017
A1: Runtime overhead (ms) | B1: Native | C1: PCCE (CCID Update) | D1: DCCE (CCID Update) | E1: PCCE (CCID Update + getCCID) | F1: DCCE (CCID Update + getCCID)
A2: 505.mcf_r | B2: 32869 | C2: 56219 | D2: 57006 | E2: 702600 | F2: 63658
A3: 508.namd_r | B3: 25970 | C3: 42521 | D3: 44332 | E3: 68627 | F3: 44415
A4: 510.parest_r | B4: 39798 | C4: 100657 | D4: 102594 | E4: 112550 | F4: 102838 | G4: segfault at push_back function???
A5: 519.lbm_r | B5: 24488 | C5: 30012 | D5: 32201 | E5: 32098 | F5: 32125 | G5: looks okay, so need to collect # of getCCID at runtime
A6: 523.xalancbmk_r | B6: 29569 | C6: 52975 | D6: 52507 | E6: 364200 | F6: 54505
A7: 525.x264_r | B7: 11043 | C7: 20051 | D7: 20886 | E7: 137310 | F7: 21456
A8: 541.leela_r | B8: 38109 | C8: 64314 | D8: 64337 | E8: 491700 | F8: 65811
A9: 557.xz_r | B9: 12007 | C9: 20046 | D9: 20200 | E9: 29961 | F9: 20047
A10: 605.mcf_s | B10: 66451 | C10: 112016 | D10: 116305 | E10: 1618600 | F10: 129930
A11: 619.lbm_s | B11: 116294 | C11: 112234 | D11: 117313 | E11: 117036 | F11: 117419 | G11: looks okay, so need to collect # of getCCID at runtime
A12: 623.xalancbmk_s | B12: 29341 | C12: 50118 | D12: 52506 | E12: 362900 | F12: 53796
A13: 625.x264_s | B13: 11136 | C13: 18811 | D13: 20806 | E13: 137400 | F13: 21453
A14: 641.leela_s | B14: 38181 | C14: 61069 | D14: 64577 | E14: 494100 | F14: 65877
A15: 657.xz_s | B15: 31298 | C15: 60957 | D15: 62900 | E15: 96640 | F15: 63540 | G15: Command terminated by signal 11
A21: Runtime Overhead | B21: Native | C21: PCCE (CCID Update) | D21: DCCE (CCID Update) | E21: PCCE (CCID Update + getCCID) | F21: DCCE (CCID Update + getCCID)
A22: mcf_r | B22: =B2/$B2 -> 1 | C22: =C2/$B2 -> 1.7103958 | D22: =D2/$B2 -> 1.7343393 | E22: =E2/$B2 -> 21.375764 | F22: =F2/$B2 -> 1.9367185
A23: namd_r | B23: =B3/$B3 -> 1 | C23: =C3/$B3 -> 1.6373123 | D23: =D3/$B3 -> 1.7070466 | E23: =E3/$B3 -> 2.6425491 | F23: =F3/$B3 -> 1.7102426
A24: parest_r | B24: =B4/$B4 -> 1 | C24: =C4/$B4 -> 2.5291974 | D24: =D4/$B4 -> 2.5778682 | E24: =E4/$B4 -> 2.8280316 | F24: =F4/$B4 -> 2.5839992
A25: lbm_r | B25: =B5/$B5 -> 1 | C25: =C5/$B5 -> 1.2255799 | D25: =D5/$B5 -> 1.3149706 | E25: =E5/$B5 -> 1.3107645 | F25: =F5/$B5 -> 1.311867
A26: xalancbmk_r | B26: =B6/$B6 -> 1 | C26: =C6/$B6 -> 1.7915723 | D26: =D6/$B6 -> 1.7757449 | E26: =E6/$B6 -> 12.316954 | F26: =F6/$B6 -> 1.8433156
A27: x264_r | B27: =B7/$B7 -> 1 | C27: =C7/$B7 -> 1.8157204 | D27: =D7/$B7 -> 1.8913339 | E27: =E7/$B7 -> 12.434121 | F27: =F7/$B7 -> 1.9429503
A28: leela_r | B28: =B8/$B8 -> 1 | C28: =C8/$B8 -> 1.6876328 | D28: =D8/$B8 -> 1.6882364 | E28: =E8/$B8 -> 12.902464 | F28: =F8/$B8 -> 1.7269149
A29: xz_r | B29: =B9/$B9 -> 1 | C29: =C9/$B9 -> 1.6695261 | D29: =D9/$B9 -> 1.682352 | E29: =E9/$B9 -> 2.4952944 | F29: =F9/$B9 -> 1.6696094
A30: mcf_s | B30: =B10/$B10 -> 1 | C30: =C10/$B10 -> 1.6856932 | D30: =D10/$B10 -> 1.750237 | E30: =E10/$B10 -> 24.357797 | F30: =F10/$B10 -> 1.9552753
A31: lbm_s | B31: =B11/$B11 -> 1 | C31: =C11/$B11 -> 0.96508848 | D31: =D11/$B11 -> 1.0087623 | E31: =E11/$B11 -> 1.0063804 | F31: =F11/$B11 -> 1.0096738
A32: xalancbmk_s | B32: =B12/$B12 -> 1 | C32: =C12/$B12 -> 1.7081217 | D32: =D12/$B12 -> 1.7895096 | E32: =E12/$B12 -> 12.368358 | F32: =F12/$B12 -> 1.8334753
A33: x264_s | B33: =B13/$B13 -> 1 | C33: =C13/$B13 -> 1.6892062 | D33: =D13/$B13 -> 1.8683549 | E33: =E13/$B13 -> 12.338362 | F33: =F13/$B13 -> 1.9264547
... A35: xz_s | B35: =B15/$B15 -> 1 | C35: =C15/$B15 -> 1.9476324 | D35: =D15/$B15 -> 2.0097131 | E35: =E15/$B15 -> 3.0877372 | F35: =F15/$B15 -> 2.0301617
A36: goemean | B36: =GEOMEAN(B22:B35) -> 1 | C36: =GEOMEAN(C22:C35) -> 1.6556977 | D36: =GEOMEAN(D22:D35) -> 1.7160725 | E36: =GEOMEAN(E22:E35) -> 6.2975928 | F36: =GEOMEAN(F22:F35) -> 1.7643231 | G36: =E36/F36 -> 3.5694102
G37: =D36/C36 -> 1.0364649
G41: MB
A42: Memory Overhead (kbytes) | B42: Native | C42: PCCE (CCID Update) | D42: DCCE (CCID Update) | E42: PCCE (CCID Update + getCCID) | F42: DCCE (CCID Update + getCCID) | G42: PCCE (CCID Update) | H42: DCCE (CCID Update) | I42: PCCE (CCID Update + getCCID) | J42: DCCE (CCID Update + getCCID)
A43: mcf_r | B43: 623988 | C43: 625992 | D43: 625828 | E43: 625968 | F43: 625804 | G43: =(C43-$B43)/1024 -> 1.9570312 | H43: =(D43-$B43)/1024 -> 1.796875 | I43: =(E43-$B43)/1024 -> 1.9335938 | J43: =(F43-$B43)/1024 -> 1.7734375
A44: namd_r | B44: 166548 | C44: 167016 | D44: 167076 | E44: 167796 | F44: 167020 | G44: =(C44-$B44)/1024 -> 0.45703125 | H44: =(D44-$B44)/1024 -> 0.515625 | I44: =(E44-$B44)/1024 -> 1.21875 | J44: =(F44-$B44)/1024 -> 0.4609375
A45: parest_r | B45: 424120 | C45: 425676 | D45: 425304 | E45: 427916 | F45: 425328 | G45: =(C45-$B45)/1024 -> 1.5195312 | H45: =(D45-$B45)/1024 -> 1.15625 | I45: =(E45-$B45)/1024 -> 3.7070312 | J45: =(F45-$B45)/1024 -> 1.1796875
A46: lbm_r | B46: 420396 | C46: 422404 | D46: 422024 | E46: 422488 | F46: 422052 | G46: =(C46-$B46)/1024 -> 1.9609375 | H46: =(D46-$B46)/1024 -> 1.5898438 | I46: =(E46-$B46)/1024 -> 2.0429688 | J46: =(F46-$B46)/1024 -> 1.6171875
A47: xalancbmk_r | B47: 490640 | C47: 495192 | D47: 494404 | E47: 504596 | F47: 494656 | G47: =(C47-$B47)/1024 -> 4.4453125 | H47: =(D47-$B47)/1024 -> 3.6757812 | I47: =(E47-$B47)/1024 -> 13.628906 | J47: =(F47-$B47)/1024 -> 3.921875
A48: x264_r | B48: 159952 | C48: 162632 | D48: 162452 | E48: 167692 | F48: 162660 | G48: =(C48-$B48)/1024 -> 2.6171875 | H48: =(D48-$B48)/1024 -> 2.4414062 | I48: =(E48-$B48)/1024 -> 7.5585938 | J48: =(F48-$B48)/1024 -> 2.6445312
A49: leela_r | B49: 27644 | C49: 28364 | D49: 28308 | E49: 29636 | F49: 28296 | G49: =(C49-$B49)/1024 -> 0.703125 | H49: =(D49-$B49)/1024 -> 0.6484375 | I49: =(E49-$B49)/1024 -> 1.9453125 | J49: =(F49-$B49)/1024 -> 0.63671875
...

Sheet Static_Overhead_Splash3
A1: Runtime overhead (ms) | B1: Native | C1: PCCE (CCID Update) | D1: DCCE (CCID Update) | E1: PCCE (CCID Update + getCCID) | F1: DCCE (CCID Update + getCCID)
A2: 701.BARNES | B2: 26 | C2: 57 | D2: 71 | E2: 410 | F2: 74 | G2: Command terminated by signal 11 | J2: 701.BARNES: malloc.c:2379: sysmalloc: Assertion `(old_top == initial_top (av) && old_size == 0) || ((unsigned long) (old_size) >= MINSIZE && prev_inuse (old_top) && ((unsigned long) old_end & (pagesize - 1)) == 0)' failed.
A3: 702.CHOLESKY | B3: 22 | C3: 23 | D3: 24 | E3: 58 | F3: 25
A4: 703.FFT | B4: 5557 | C4: 5691 | D4: 6498 | E4: 14340 | F4: 6214
A5: 704.FMM | B5: 44 | C5: 41 | D5: 42 | E5: 75 | F5: 43 | G5: Command terminated by signal 11
A6: 705.LU-CB | B6: 2625 | C6: 4677 | D6: 4781 | E6: 29042 | F6: 4553
A7: 706.LU-NCB | B7: 3865 | C7: 5879 | D7: 5516 | E7: 30555 | F7: 5821
A8: 707.OCEAN-CP | B8: 1809 | C8: 1821 | D8: 1822 | E8: 1842 | F8: 1823
A9: 708.OCEAN-NCP | B9: 3764 | C9: 3685 | D9: 3711 | E9: 3712 | F9: 3799
A10: 709.RADIOSITY | B10: 31 | C10: 83 | D10: 98 | E10: 894 | F10: 106 | G10: Command terminated by signal 11
A11: 710.RADIX | B11: 949 | C11: 1284 | D11: 1289 | E11: 7754 | F11: 1320
A12: 713.WATER-NSQUARED | B12: 472 | C12: 650 | D12: 693 | E12: 3253 | F12: 768
A13: 714.WATER-SPATIAL | B13: 54 | C13: 81 | D13: 83 | E13: 339 | F13: 91
A16: Runtime Overhead | B16: Native | C16: PCCE (CCID Update) | D16: DCCE (CCID Update) | E16: PCCE (CCID Update + getCCID) | F16: DCCE (CCID Update + getCCID)
A17: BARNES | B17: =B2/$B2 -> 1 | C17: =C2/$B2 -> 2.1923077 | D17: =D2/$B2 -> 2.7307692 | E17: =E2/$B2 -> 15.769231 | F17: =F2/$B2 -> 2.8461538
A18: CHOLESKY | B18: =B3/$B3 -> 1 | C18: =C3/$B3 -> 1.0454545 | D18: =D3/$B3 -> 1.0909091 | E18: =E3/$B3 -> 2.6363636 | F18: =F3/$B3 -> 1.1363636
A19: FFT | B19: =B4/$B4 -> 1 | C19: =C4/$B4 -> 1.0241137 | D19: =D4/$B4 -> 1.169336 | E19: =E4/$B4 -> 2.5805291 | F19: =F4/$B4 -> 1.1182293
A20: FMM | B20: =B5/$B5 -> 1 | C20: =C5/$B5 -> 0.93181818 | D20: =D5/$B5 -> 0.95454545 | E20: =E5/$B5 -> 1.7045455 | F20: =F5/$B5 -> 0.97727273
A21: LU-CB | B21: =B6/$B6 -> 1 | C21: =C6/$B6 -> 1.7817143 | D21: =D6/$B6 -> 1.8213333 | E21: =E6/$B6 -> 11.063619 | F21: =F6/$B6 -> 1.7344762
A22: LU-NCB | B22: =B7/$B7 -> 1 | C22: =C7/$B7 -> 1.5210867 | D22: =D7/$B7 -> 1.4271669 | E22: =E7/$B7 -> 7.9055627 | F22: =F7/$B7 -> 1.5060802
A23: OCEAN-CP | B23: =B8/$B8 -> 1 | C23: =C8/$B8 -> 1.0066335 | D23: =D8/$B8 -> 1.0071863 | E23: =E8/$B8 -> 1.0182421 | F23: =F8/$B8 -> 1.0077391
A24: OCEAN-NCP | B24: =B9/$B9 -> 1 | C24: =C9/$B9 -> 0.97901169 | D24: =D9/$B9 -> 0.98591923 | E24: =E9/$B9 -> 0.98618491 | F24: =F9/$B9 -> 1.0092986
A25: RADIOSITY | B25: =B10/$B10 -> 1 | C25: =C10/$B10 -> 2.6774194 | D25: =D10/$B10 -> 3.1612903 | E25: =E10/$B10 -> 28.83871 | F25: =F10/$B10 -> 3.4193548
A26: RADIX | B26: =B11/$B11 -> 1 | C26: =C11/$B11 -> 1.3530032 | D26: =D11/$B11 -> 1.3582719 | E26: =E11/$B11 -> 8.170706 | F26: =F11/$B11 -> 1.3909378
A27: WATER-NSQUARED | B27: =B12/$B12 -> 1 | C27: =C12/$B12 -> 1.3771186 | D27: =D12/$B12 -> 1.4682203 | E27: =E12/$B12 -> 6.8919492 | F27: =F12/$B12 -> 1.6271186
A28: WATER-SPATIAL | B28: =B13/$B13 -> 1 | C28: =C13/$B13 -> 1.5 | D28: =D13/$B13 -> 1.537037 | E28: =E13/$B13 -> 6.2777778 | F28: =F13/$B13 -> 1.6851852
A29: goemean | B29: =GEOMEAN(B17:B28) -> 1 | C29: =GEOMEAN(C17:C28) -> 1.3699917 | D29: =GEOMEAN(D17:D28) -> 1.4454263 | E29: =GEOMEAN(E17:E28) -> 4.8362974 | F29: =GEOMEAN(F17:F28) -> 1.4928017 | G29: =E29/F29 -> 3.2397455
G33: =D29/C29 -> 1.0550621
A37: Memory Overhead (kbytes) | B37: Native | C37: PCCE (CCID Update) | D37: DCCE (CCID Update) | E37: PCCE (CCID Update + getCCID) | F37: DCCE (CCID Update + getCCID) | G37: PCCE (CCID Update) | H37: DCCE (CCID Update) | I37: PCCE (CCID Update + getCCID) | J37: DCCE (CCID Update + getCCID)
A38: BARNES | B38: 5360 | C38: 7224 | D38: 6888 | E38: 7156 | F38: 6884 | G38: =(C38-$B38)/1024 -> 1.8203125 | H38: =(D38-$B38)/1024 -> 1.4921875 | I38: =(E38-$B38)/1024 -> 1.7539062 | J38: =(F38-$B38)/1024 -> 1.4882812 | K38: =I38-J38 -> 0.265625
A39: CHOLESKY | B39: 41536 | C39: 44076 | D39: 44008 | E39: 43832 | F39: 43944 | G39: =(C39-$B39)/1024 -> 2.4804688 | H39: =(D39-$B39)/1024 -> 2.4140625 | I39: =(E39-$B39)/1024 -> 2.2421875 | J39: =(F39-$B39)/1024 -> 2.3515625 | K39: =I39-J39 -> -0.109375
A40: FFT | B40: 12587144 | C40: 12589148 | D40: 12589072 | E40: 12589168 | F40: 12588864 | G40: =(C40-$B40)/1024 -> 1.9570312 | H40: =(D40-$B40)/1024 -> 1.8828125 | I40: =(E40-$B40)/1024 -> 1.9765625 | J40: =(F40-$B40)/1024 -> 1.6796875 | K40: =I40-J40 -> 0.296875
A41: FMM | B41: 26204 | C41: 27948 | D41: 27652 | E41: 27920 | F41: 27744 | G41: =(C41-$B41)/1024 -> 1.703125 | H41: =(D41-$B41)/1024 -> 1.4140625 | I41: =(E41-$B41)/1024 -> 1.6757812 | J41: =(F41-$B41)/1024 -> 1.5039062 | K41: =I41-J41 -> 0.171875
A42: LU-CB | B42: 133964 | C42: 135920 | D42: 135776 | E42: 135900 | F42: 135804 | G42: =(C42-$B42)/1024 -> 1.9101562 | H42: =(D42-$B42)/1024 -> 1.7695312 | I42: =(E42-$B42)/1024 -> 1.890625 | J42: =(F42-$B42)/1024 -> 1.796875 | K42: =I42-J42 -> 0.09375
A43: LU-NCB | B43: 133440 | C43: 135404 | D43: 135256 | E43: 135540 | F43: 135344 | G43: =(C43-$B43)/1024 -> 1.9179688 | H43: =(D43-$B43)/1024 -> 1.7734375 | I43: =(E43-$B43)/1024 -> 2.0507812 | J43: =(F43-$B43)/1024 -> 1.859375 | K43: =I43-J43 -> 0.19140625
A44: OCEAN-CP | B44: 3629736 | C44: 3631776 | D44: 3631788 | E44: 3631860 | F44: 3631688 | G44: =(C44-$B44)/1024 -> 1.9921875 | H44: =(D44-$B44)/1024 -> 2.0039062 | I44: =(E44-$B44)/1024 -> 2.0742188 | J44: =(F44-$B44)/1024 -> 1.90625 | K44: =I44-J44 -> 0.16796875
A45: OCEAN-NCP | B45: 4092668 | C45: 4094604 | D45: 4094596 | E45: 4094656 | F45: 4094376 | G45: =(C45-$B45)/1024 -> 1.890625 | H45: =(D45-$B45)/1024 -> 1.8828125 | I45: =(E45-$B45)/1024 -> 1.9414062 | J45: =(F45-$B45)/1024 -> 1.6679688 | K45: =I45-J45 -> 0.2734375
A46: RADIOSITY | B46: 219128 | C46: 220972 | D46: 220688 | E46: 221176 | F46: 220900 | G46: =(C46-$B46)/1024 -> 1.8007812 | H46: =(D46-$B46)/1024 -> 1.5234375 | I46: =(E46-$B46)/1024 -> 2 | J46: =(F46-$B46)/1024 -> 1.7304688 | K46: =I46-J46 -> 0.26953125
A47: RADIX | B47: 1440684 | C47: 1442876 | D47: 1442688 | E47: 1442708 | F47: 1442508 | G47: =(C47-$B47)/1024 -> 2.140625 | H47: =(D47-$B47)/1024 -> 1.9570312 | I47: =(E47-$B47)/1024 -> 1.9765625 | J47: =(F47-$B47)/1024 -> 1.78125 | K47: =I47-J47 -> 0.1953125
A48: WATER-NSQUARED | B48: 6708 | C48: 8700 | D48: 8532 | E48: 8736 | F48: 8488 | G48: =(C48-$B48)/1024 -> 1.9453125 | H48: =(D48-$B48)/1024 -> 1.78125 | I48: =(E48-$B48)/1024 -> 1.9804688 | J48: =(F48-$B48)/1024 -> 1.7382812 | K48: =I48-J48 -> 0.2421875
...

Sheet Dyn_Overhead_SPEC2017
A1: Runtime overhead (ms) | B1: Native | C1: Empty client | D1: DrCCTProf (CCID Update) | E1: DCCE (CCID Update) | F1: DrCCTProf (CCID Update + getCCID) | G1: DCCE (CCID Update + getCCID)
A2: 505.mcf_r | B2: 32869 | C2: 61249 | D2: 393700 | E2: 322373 | F2: 458800 | G2: 388900
A3: 508.namd_r | B3: 25970 | C3: 44619 | D3: 56892 | E3: 51233 | F3: 58866 | G3: 52843
A4: 510.parest_r | B4: 39798 | C4: 104067 | D4: 181311 | E4: 143485 | F4: 195831 | G4: 157595
A5: 519.lbm_r | B5: 24488 | C5: 41939 | D5: 41541 | E5: 41794 | F5: 41833 | G5: 41701
A6: 523.xalancbmk_r | B6: 29569 | C6: 55325 | D6: 226761 | E6: 143741 | F6: 260709 | G6: 176264
A7: 525.x264_r | B7: 11043 | C7: 23148 | D7: 80574 | E7: 62939 | F7: 92039 | G7: 73311
A8: 541.leela_r | B8: 38109 | C8: 71140 | D8: 277611 | E8: 164814 | F8: 315309 | G8: 196404
A9: 557.xz_r | B9: 12007 | C9: 20963 | D9: 27253 | E9: 24849 | F9: 28443 | G9: 25916
A10: 605.mcf_s | B10: 66451 | C10: 124404 | D10: 766000 | E10: 625600 | F10: 881100 | G10: 754600
A11: 619.lbm_s | B11: 116294 | C11: 122291 | D11: 118549 | E11: 118093 | F11: 118090 | G11: 118523
A12: 623.xalancbmk_s | B12: 29341 | C12: 54869 | D12: 226410 | E12: 141824 | F12: 260330 | G12: 174995
A13: 625.x264_s | B13: 11136 | C13: 23149 | D13: 80515 | E13: 62926 | F13: 91966 | G13: 73369
... A15: 657.xz_s | B15: 31298 | C15: 64447 | D15: 81707 | E15: 76384 | F15: 85929 | G15: 80178
A21: Runtime Overhead | B21: Native | C21: Empty client | D21: DrCCTProf (CCID Update) | E21: DCCE (CCID Update) | F21: DrCCTProf (CCID Update+getCCID) | G21: DCCE (CCID Update+getCCID) | I21: Runtime Overhead | J21: Empty client | K21: DrCCTProf (CCID Update) | L21: DCCE (CCID Update) | M21: DrCCTProf (CCID Update+getCCID) | N21: DCCE (CCID Update+getCCID)
A22: mcf_r | B22: =B2/$B2 -> 1 | C22: =C2/$B2 -> 1.8634275 | D22: =D2/$B2 -> 11.977851 | E22: =E2/$B2 -> 9.8078128 | F22: =F2/$B2 -> 13.958441 | G22: =G2/$B2 -> 11.831817 | I22: mcf_r | J22: =C2/$C2 -> 1 | K22: =D2/$C2 -> 6.42786 | L22: =E2/$C2 -> 5.2633186 | M22: =F2/$C2 -> 7.4907345 | N22: =G2/$C2 -> 6.3494914
A23: namd_r | B23: =B3/$B3 -> 1 | C23: =C3/$B3 -> 1.7180978 | D23: =D3/$B3 -> 2.1906816 | E23: =E3/$B3 -> 1.9727763 | F23: =F3/$B3 -> 2.2666923 | G23: =G3/$B3 -> 2.0347709 | I23: namd_r | J23: =C3/$C3 -> 1 | K23: =D3/$C3 -> 1.2750622 | L23: =E3/$C3 -> 1.1482328 | M23: =F3/$C3 -> 1.3193034 | N23: =G3/$C3 -> 1.1843161
A24: parest_r | B24: =B4/$B4 -> 1 | C24: =C4/$B4 -> 2.6148801 | D24: =D4/$B4 -> 4.5557817 | E24: =E4/$B4 -> 3.6053319 | F24: =F4/$B4 -> 4.9206242 | G24: =G4/$B4 -> 3.9598724 | I24: parest_r | J24: =C4/$C4 -> 1 | K24: =D4/$C4 -> 1.7422526 | L24: =E4/$C4 -> 1.3787752 | M24: =F4/$C4 -> 1.8817781 | N24: =G4/$C4 -> 1.5143609
A25: lbm_r | B25: =B5/$B5 -> 1 | C25: =C5/$B5 -> 1.7126348 | D25: =D5/$B5 -> 1.6963819 | E25: =E5/$B5 -> 1.7067135 | F25: =F5/$B5 -> 1.7083061 | G25: =G5/$B5 -> 1.7029157 | I25: lbm_r | J25: =C5/$C5 -> 1 | K25: =D5/$C5 -> 0.99051003 | L25: =E5/$C5 -> 0.9965426 | M25: =F5/$C5 -> 0.99747252 | N25: =G5/$C5 -> 0.99432509
A26: xalancbmk_r | B26: =B6/$B6 -> 1 | C26: =C6/$B6 -> 1.8710474 | D26: =D6/$B6 -> 7.6688762 | E26: =E6/$B6 -> 4.861206 | F26: =F6/$B6 -> 8.8169705 | G26: =G6/$B6 -> 5.9611079 | I26: xalancbmk_r | J26: =C6/$C6 -> 1 | K26: =D6/$C6 -> 4.0987076 | L26: =E6/$C6 -> 2.5981202 | M26: =F6/$C6 -> 4.7123181 | N26: =G6/$C6 -> 3.1859738
A27: x264_r | B27: =B7/$B7 -> 1 | C27: =C7/$B7 -> 2.0961695 | D27: =D7/$B7 -> 7.2963869 | E27: =E7/$B7 -> 5.6994476 | F27: =F7/$B7 -> 8.3346011 | G27: =G7/$B7 -> 6.6386851 | I27: x264_r | J27: =C7/$C7 -> 1 | K27: =D7/$C7 -> 3.4808191 | L27: =E7/$C7 -> 2.7189822 | M27: =F7/$C7 -> 3.9761102 | N27: =G7/$C7 -> 3.1670555
A28: leela_r | B28: =B8/$B8 -> 1 | C28: =C8/$B8 -> 1.8667506 | D28: =D8/$B8 -> 7.2846572 | E28: =E8/$B8 -> 4.3248052 | F28: =F8/$B8 -> 8.2738723 | G28: =G8/$B8 -> 5.1537432 | I28: leela_r | J28: =C8/$C8 -> 1 | K28: =D8/$C8 -> 3.9023194 | L28: =E8/$C8 -> 2.3167557 | M28: =F8/$C8 -> 4.4322322 | N28: =G8/$C8 -> 2.7608097
A29: xz_r | B29: =B9/$B9 -> 1 | C29: =C9/$B9 -> 1.7458982 | D29: =D9/$B9 -> 2.2697593 | E29: =E9/$B9 -> 2.0695428 | F29: =F9/$B9 -> 2.3688682 | G29: =G9/$B9 -> 2.1584076 | I29: xz_r | J29: =C9/$C9 -> 1 | K29: =D9/$C9 -> 1.3000525 | L29: =E9/$C9 -> 1.1853742 | M29: =F9/$C9 -> 1.3568192 | N29: =G9/$C9 -> 1.2362734
A30: mcf_s | B30: =B10/$B10 -> 1 | C30: =C10/$B10 -> 1.8721163 | D30: =D10/$B10 -> 11.527291 | E30: =E10/$B10 -> 9.4144558 | F30: =F10/$B10 -> 13.259394 | G30: =G10/$B10 -> 11.355736 | I30: mcf_s | J30: =C10/$C10 -> 1 | K30: =D10/$C10 -> 6.1573583 | L30: =E10/$C10 -> 5.0287772 | M30: =F10/$C10 -> 7.0825697 | N30: =G10/$C10 -> 6.0657214
A31: lbm_s | B31: =B11/$B11 -> 1 | C31: =C11/$B11 -> 1.0515676 | D31: =D11/$B11 -> 1.0193905 | E31: =E11/$B11 -> 1.0154694 | F31: =F11/$B11 -> 1.0154436 | G31: =G11/$B11 -> 1.0191669 | I31: lbm_s | J31: =C11/$C11 -> 1 | K31: =D11/$C11 -> 0.96940086 | L31: =E11/$C11 -> 0.96567204 | M31: =F11/$C11 -> 0.96564751 | N31: =G11/$C11 -> 0.96918825
A32: xalancbmk_s | B32: =B12/$B12 -> 1 | C32: =C12/$B12 -> 1.8700453 | D32: =D12/$B12 -> 7.7165059 | E32: =E12/$B12 -> 4.8336458 | F32: =F12/$B12 -> 8.8725674 | G32: =G12/$B12 -> 5.9641798 | I32: xalancbmk_s | J32: =C12/$C12 -> 1 | K32: =D12/$C12 -> 4.1263737 | L32: =E12/$C12 -> 2.5847746 | M32: =F12/$C12 -> 4.7445734 | N32: =G12/$C12 -> 3.1893237
A33: x264_s | B33: =B13/$B13 -> 1 | C33: =C13/$B13 -> 2.0787536 | D33: =D13/$B13 -> 7.2301545 | E33: =E13/$B13 -> 5.6506825 | F33: =F13/$B13 -> 8.2584411 | G33: =G13/$B13 -> 6.5884519 | I33: x264_s | J33: =C13/$C13 -> 1 | K33: =D13/$C13 -> 3.47812 | L33: =E13/$C13 -> 2.7183032 | M33: =F13/$C13 -> 3.972785 | N33: =G13/$C13 -> 3.1694242
... A35: xz_s | B35: =B15/$B15 -> 1 | C35: =C15/$B15 -> 2.0591412 | D35: =D15/$B15 -> 2.6106141 | E35: =E15/$B15 -> 2.4405393 | F35: =F15/$B15 -> 2.7455109 | G35: =G15/$B15 -> 2.5617611 | I35: xz_s | J35: =C15/$C15 -> 1 | K35: =D15/$C15 -> 1.267817 | L35: =E15/$C15 -> 1.185222 | M35: =F15/$C15 -> 1.3333282 | N35: =G15/$C15 -> 1.244092
A36: goemean | B36: =GEOMEAN(B22:B35) -> 1 | C36: =GEOMEAN(C22:C35) -> 1.8476182 | D36: =GEOMEAN(D22:D35) -> 4.6655435 | E36: =GEOMEAN(E22:E35) -> 3.6745827 | F36: =GEOMEAN(F22:F35) -> 5.1245445 | G36: =GEOMEAN(G22:G35) -> 4.1373752 | H36: =F36/G36 -> 1.238598 | I36: goemean | J36: =GEOMEAN(J22:J35) -> 1 | K36: =GEOMEAN(K22:K35) -> 2.5251665 | L36: =GEOMEAN(L22:L35) -> 1.9888215 | M36: =GEOMEAN(M22:M35) -> 2.773595 | N36: =GEOMEAN(N22:N35) -> 2.2393021
A42: Memory Overhead (kbytes) | B42: Native | C42: Empty client | D42: DrCCTProf (CCID Update) | E42: DCCE (CCID Update) | F42: DrCCTProf (CCID Update+getCCID) | G42: DCCE (CCID Update+getCCID) | H42: Empty client | I42: DrCCTProf (CCID Update) | J42: DCCE (CCID Update) | K42: DrCCTProf (CCID Update+getCCID) | L42: DCCE (CCID Update+getCCID)
A43: mcf_r | B43: 623988 | C43: 631656 | D43: 679972 | E43: 632524 | F43: 680084 | G43: 632620 | H43: =(C43-$B43)/1024 -> 7.4882812 | I43: =(D43-$B43)/1024 -> 54.671875 | J43: =(E43-$B43)/1024 -> 8.3359375 | K43: =(F43-$B43)/1024 -> 54.78125 | L43: =(G43-$B43)/1024 -> 8.4296875 | M43: =K43-L43 -> 46.351562
A44: namd_r | B44: 166548 | C44: 174952 | D44: 235356 | E44: 176120 | F44: 235524 | G44: 176192 | H44: =(C44-$B44)/1024 -> 8.2070312 | I44: =(D44-$B44)/1024 -> 67.195312 | J44: =(E44-$B44)/1024 -> 9.3476562 | K44: =(F44-$B44)/1024 -> 67.359375 | L44: =(G44-$B44)/1024 -> 9.4179688 | M44: =K44-L44 -> 57.941406
A45: parest_r | B45: 424120 | C45: 532096 | D45: 1837868 | E45: 535876 | F45: 1839932 | G45: 537444 | H45: =(C45-$B45)/1024 -> 105.44531 | I45: =(D45-$B45)/1024 -> 1380.6133 | J45: =(E45-$B45)/1024 -> 109.13672 | K45: =(F45-$B45)/1024 -> 1382.6289 | L45: =(G45-$B45)/1024 -> 110.66797 | M45: =K45-L45 -> 1271.9609
A46: lbm_r | B46: 420396 | C46: 427684 | D46: 472928 | E46: 428808 | F46: 473264 | G46: 428680 | H46: =(C46-$B46)/1024 -> 7.1171875 | I46: =(D46-$B46)/1024 -> 51.300781 | J46: =(E46-$B46)/1024 -> 8.2148438 | K46: =(F46-$B46)/1024 -> 51.628906 | L46: =(G46-$B46)/1024 -> 8.0898438 | M46: =K46-L46 -> 43.539062
A47: xalancbmk_r | B47: 490640 | C47: 508848 | D47: 739320 | E47: 511764 | F47: 741216 | G47: 513348 | H47: =(C47-$B47)/1024 -> 17.78125 | I47: =(D47-$B47)/1024 -> 242.85156 | J47: =(E47-$B47)/1024 -> 20.628906 | K47: =(F47-$B47)/1024 -> 244.70312 | L47: =(G47-$B47)/1024 -> 22.175781 | M47: =K47-L47 -> 222.52734
A48: x264_r | B48: 159952 | C48: 172224 | D48: 275884 | E48: 176780 | F48: 273232 | G48: 177136 | H48: =(C48-$B48)/1024 -> 11.984375 | I48: =(D48-$B48)/1024 -> 113.21484 | J48: =(E48-$B48)/1024 -> 16.433594 | K48: =(F48-$B48)/1024 -> 110.625 | L48: =(G48-$B48)/1024 -> 16.78125 | M48: =K48-L48 -> 93.84375
A49: leela_r | B49: 27644 | C49: 86128 | D49: 333520 | E49: 87252 | F49: 333976 | G49: 87420 | H49: =(C49-$B49)/1024 -> 57.113281 | I49: =(D49-$B49)/1024 -> 298.70703 | J49: =(E49-$B49)/1024 -> 58.210938 | K49: =(F49-$B49)/1024 -> 299.15234 | L49: =(G49-$B49)/1024 -> 58.375 | M49: =K49-L49 -> 240.77734
A50: xz_r | B50: 743004 | C50: 751400 | D50: 797204 | E50: 752772 | F50: 797372 | G50: 752864 | H50: =(C50-$B50)/1024 -> 8.1992188 | I50: =(D50-$B50)/1024 -> 52.929688 | J50: =(E50-$B50)/1024 -> 9.5390625 | K50: =(F50-$B50)/1024 -> 53.09375 | L50: =(G50-$B50)/1024 -> 9.6289062 | M50: =K50-L50 -> 43.464844
